Workbook

Sheet All docs
B1: PROIEL STATUS | C1: στο PROIEL annotated/ready for valency analysis | D1: στο PROIEL/reviewed/ready for annotation | E1: στο PROEIL/under review | F1: σε προ-επεξεργασία για εισαγωγή στο PROIEL
C2: ΠΡΩΤΗ ΦΑΣΗ | P2: treebank file
A3: Canonical ID | C3: Title/Author | D3: Source text/Translation | E3: Period | F3: Language | G3: PROIEL link | H3: Status | I3: Next step | J3: Contributors so far | K3: Currently handled by | L3: Original Format | M3: Original Download method | N3: Comments | O3: Original Source | Q3: Notes | R3: Script (if any)
A4: athdgc.001.001.001.lat.006.v1 | B4: added | C4: Jerome's Vulgate | D4: Translation | E4: 4th century CE | F4: Latin | G4: Jerome's Vulgate | H4: Uploaded to Proiel | I4: To be analysed | L4: proiel treebank | M4: proiel treebank | O4: ./data/syntacticus-treebank-data/proiel/latin-nt-1.xml | P4: ./data/syntacticus-treebank-data/proiel/latin-nt-1.xml
A5: athdgc.011.001.lat.000.000.v1 | B5: added | C5: Caesar: Commentarii belli Gallici | D5: Source text | E5: 1st century BCE | F5: Latin | G5: Caesar: Commentarii belli Gallici | H5: Uploaded to Proiel | I5: To be analysed | L5: proiel treebank | M5: proiel treebank | O5: ./data/syntacticus-treebank-data/proiel/caes-gal-1.xml | P5: ./data/syntacticus-treebank-data/proiel/caes-gal-1.xml
A6: athdgc.012.001.lat.000.000.v1 | B6: added | C6: Cicero: Epistulae ad Atticum | D6: Source text | E6: 1st century BCE | F6: Latin | G6: Cicero: Epistulae ad Atticum | H6: Uploaded to Proiel | I6: To be analysed | L6: proiel treebank | M6: proiel treebank | O6: ./data/syntacticus-treebank-data/proiel/cic-att-1.xml | P6: ./data/syntacticus-treebank-data/proiel/cic-att-1.xml
A7: athdgc.012.002.lat.000.000.v1 | B7: added | C7: Cicero: De officiis | D7: Source text | E7: 1st century BCE | F7: Latin | G7: Cicero: De officiis | H7: Uploaded to Proiel | I7: To be analysed | L7: proiel treebank | M7: proiel treebank | O7: ./data/syntacticus-treebank-data/proiel/cic-off-1.xml | P7: ./data/syntacticus-treebank-data/proiel/cic-off-1.xml
A8: athdgc.025.001.lat.000.000.v1 | B8: added | C8: Palladius: Opus agriculturae | D8: Source text | E8: 5th century CE | F8: Latin | G8: Palladius: Opus agriculturae | H8: Uploaded to Proiel | I8: To be analysed | L8: proiel treebank | M8: proiel treebank | O8: ./data/syntacticus-treebank-data/proiel/pal-agr-1.xml | P8: ./data/syntacticus-treebank-data/proiel/pal-agr-1.xml
A9: athdgc.006.001.lat.000.000.v1 | B9: added | C9: Peregrinatio Aetheriae | D9: Source text | E9: 4th century CE | F9: Latin | G9: Peregrinatio Aetheriae | H9: Uploaded to Proiel | I9: To be analysed | L9: proiel treebank | M9: proiel treebank | O9: ./data/syntacticus-treebank-data/proiel/per-aeth-1.xml | P9: ./data/syntacticus-treebank-data/proiel/per-aeth-1.xml
A10: athdgc.001.001.001.got.007.v1 | B10: added | C10: Wulfila Bible | D10: Source text | E10: 4th century CE | F10: Old Gothic | G10: The Gothic Bible | H10: Uploaded to Proiel | I10: To be analysed | L10: proiel treebank | M10: proiel treebank | O10: ./data/syntacticus-treebank-data/proiel/gothic-nt-v2.0.xml | P10: ./data/syntacticus-treebank-data/proiel/gothic-nt-v2.0.xml
A11: athdgc.002.016.fro.000.000.v1 | B11: added | C11: La Vie Saint Eustace | D11: Source text | E11: 12th century CE | F11: Old French | G11: La Vie Saint Eustace | H11: Uploaded to Proiel | I11: To be analysed | L11: proiel treebank | M11: proiel treebank | O11: ./data/iswoc-treebank/eustace-1.xml | P11: ./data/iswoc-treebank/eustace-1.xml
A12: athdgc.002.005.ang.000.000.v1 | B12: added | C12: Orosius | D12: Source text | E12: 5th century CE | F12: Old English | G12: Orosius | H12: Uploaded to Proiel | I12: To be analysed | L12: proiel treebank | M12: proiel treebank | O12: ./data/iswoc-treebank/or-1.xml | P12: ./data/iswoc-treebank/or-1.xml
A13: athdgc.001.001n.grc.ang.002.v1 | B13: added | C13: West-Saxon Gospels | D13: Translation | E13: 10th century CE | F13: Old English | G13: West-Saxon Gospels | H13: Uploaded to Proiel | I13: To be analysed | L13: proiel treebank | M13: proiel treebank | O13: ./data/iswoc-treebank/wscp-1.xml | P13: ./data/iswoc-treebank/wscp-1.xml
A14: athdgc.002.006.ang.000.000.v1 | B14: added | C14: Anglo-Saxon Chronicles | D14: Source text | E14: 9th - 12th century CE | F14: Old English | G14: Anglo-Saxon Chronicles | H14: Uploaded to Proiel | I14: To be analysed | L14: proiel treebank | M14: proiel treebank | O14: ./data/iswoc-treebank/chrona-1.xml | P14: ./data/iswoc-treebank/chrona-1.xml
A15: athdgc.004.001.ang.000.000.v1 | B15: added | C15: Ælfric's Lives of Saints | D15: Source text | E15: 10th century CE | F15: Old English | G15: Ælfric's Lives of Saints | H15: Uploaded to Proiel | I15: To be analysed | L15: proiel treebank | M15: proiel treebank | O15: ./data/iswoc-treebank/æls.xml | P15: ./data/iswoc-treebank/æls.xml
... A19: athdgc.018.001.grc.000.000.v1 | B19: added | C19: Histories - by Herodotus | D19: Source text | E19: 5th century BCE | F19: Ancient Greek | G19: Herodotus: Histories | H19: Uploaded to Proiel | I19: To be reviewed | L19: proiel treebank | M19: proiel treebank | O19: ./data/syntacticus-treebank-data/proiel/hdt.xml | P19: ./data/syntacticus-treebank-data/proiel/hdt.xml
A20: athdgc.029.001.grc.eng.025.v1 | B20: added | C20: Sophocles- Antigone | D20: Translation | E20: 19th century | F20: Modern English | G20: Sophocles: Antigone-TEST1 | H20: To be downloaded | I20: To be preprocessed | J20: Natasa | K20: Natasa | L20: CanonicalLit | M20: automated script | N20: structured info, no treebank available | O20: https://scaife.perseus.org/reader/urn:cts:greekLit:tlg0011.tlg002.perseus-eng2:1-80/, ./PerseusDL/canonical-greekLit/data/tlg0011/tlg002/tlg0011.tlg002.perseus-eng2.xml | P20: ./data/tlg0011.tlg002.perseus-eng2-canoncallit-test1-stage1.xml | R20: readCanonicalLit-Sophocles-Antigone-eng2-test1.ipynb
A21: athdgc.003.001.eng.000.000.v1 | B21: added | C21: Pride and Prejudice | D21: Source text | E21: 19th century CE | F21: Modern English | G21: Jane Austen: Pride and Prejudice | H21: Reviewed in Proiel | I21: To be annotated | J21: Eleni, Vangelis | K21: Sofia | L21: docx | M21: automated script | N21: Sent by email to Thodoris | O21: Gutenberg
A22: athdgc.001.001.001.eng.005.v1 | B22: added | C22: Young's Literal Translation | D22: Translation | E22: 1862 | F22: Modern English | G22: Robert Young: Young's Literal Translation-TEST2 | H22: Uploaded to Proiel | I22: To be reviewed | J22: Eleni | K22: Theodoros | L22: PDF | M22: automated script | N22: On OSF | O22: https://ebible.org/engylt/, ./data/Young\'s_literal_translation_of_the_Bible-with-tags.txt | P22: ./data/Youngs_literal_translation_of_the_Bible-text-eng-test2-stage1.xml | Q22: a) some sections are empty like Samuel 2, b) replace "--" with ":" -- έχουν φύγει, ενώ κανονικά αντι στοιχεί σε παύλα, και οι λέξεις που χώριζε έχουν ενωθεί, π.χ. Exodus 23-5 (it--thou -> itthou) | R22: readStructuredText-Youngs-Bible-eng-test2.ipynb
A23: athdgc.001.002.eng.000.000.v1 | B23: added | C23: The Tale of Beowulf | D23: Translation | E23: 19th century | F23: Modern English [from Medieval Greek] | G23: A.J. Wyatt: The Tale of Beowulf Sometime King of the Folk of the Weder Geats-TEST2 | H23: Uploaded to Proiel | I23: To be reviewed | J23: Sofia | K23: Sofia | L23: online | M23: automated script | O23: https://en.wikisource.org/wiki/The_Tale_of_Beowulf, ./data/TheTaleofBeowulf_Wyatt-2025-10.json | P23: ./data/TheTaleofBeowulf_Wyatt-html-eng-test2-stage1.xml | Q23: first letter in missing each chapter//metadata done, corrected | R23: readStructuredText-TheTaleofBeowulf-Wyatt-eng-test2.ipynb
A24: athdgc.001.001n.grc.eng.004.v1 | B24: added | C24: Tyndale's Bible - New Testament | D24: Translation | E24: 1526 | F24: Early Modern English | G24: William Tyndale: The first New Testament printed in English-New Testament-TEST2 | H24: Uploaded to Proiel | I24: To be reviewed | J24: Thodoris | K24: Sofia | M24: automated script | O24: ./data/Tyndale-NewTestament-only.txt | P24: ./data/BibleTydel-NT-txt-test3-stage1.xml | Q24: Missing i The gospell of Saynct Mathew, this is in the New Testament.txt biut parser ignores | R24: ParseTydel-NewTestament-GemXMLwithimprovements-SET5(based on Planoudis).ipynb
A25: athdgc.001.001.001.enm.003.v1 | B25: added | C25: Wycliffe Bible | D25: Translation | E25: 1382 | F25: Middle English | G25: John Wycliffe: Bible John Wycliff translation-TEST1 | H25: Uploaded to Proiel | I25: To be reviewed | J25: Sophia, Eleni | K25: Sofia | L25: docx | M25: automated script | N25: On OSF | O25: Wikisource
A26: athdgc.016.001.enm.000.000.v1 | B26: added | C26: Canterbury Tales | D26: Source text | E26: 15th century CE | F26: Middle English | G26: Geoffrey Chaucer: Canterbury tales-TEST1 | H26: Uploaded to Proiel | I26: To be reviewed | J26: Thodoris | K26: Sofia | L26: txt | M26: automated script | O26: LLDS (Literary and Linguistic Data Service) of Oxford
A27: athdgc.001.001o.grc.eng.004.v1 | B27: added | C27: Tyndale's Bible - Old Testament | D27: Translation | E27: 1526 | F27: Early Modern English | G27: William Tyndale: The first New Testament printed in English-Old Testament-TEST2 | H27: Uploaded to Proiel | I27: Reviewed | J27: Thodoris | K27: Sofia | M27: automated script
A28: athdgc.002.007.ang.000.000.v1 | B28: added | C28: Lay le Freine | D28: Source text | E28: late 13th-14th century | F28: Middle English | G28: Anonymous: Lay le Freine-Middle English Breton Lays-TEST2 | H28: Uploaded to Proiel | I28: Reviewed | J28: Eleni | K28: Sofia | L28: docx | M28: automated script | N28: Sent by email to Thodoris | O28: METS, ./data/Lay-le-Freine-2025-08.html | P28: ./data/Lay-le-Freine-html-ang-test2-stage1.xml | Q28: line 30-erase 1/ l. 56 erase 2/ l. 128 erase 3/ l.117 erase 4/l. 125 erase 5/ l. 139 erase 6 | R28: readStructuredText-Lay le Freine-ang-test2.ipynb
A29: athdgc.032.001.enm.000.000.v1 | B29: added | C29: The Vision of Piers Plowman | D29: Source text | E29: 14th century CE | F29: Middle English | G29: WilliamLangland: William Langland's The vision of Piers Plowman-TEST1 | H29: Uploaded to Proiel | I29: Reviewed | J29: Eleni, Sofia | K29: Sofia | L29: docx | M29: automated script | N29: Sent by email to Thodoris | O29: Michigan Library
A30: athdgc.002.010.enm.000.000.v1 | B30: added | C30: Sir Gawain and the Green Knight | D30: Source text | E30: 14th century CE | F30: Middle English | G30: anonymous: Sir Gawain and the Green Knight-TEST1 | H30: Uploaded to Proiel | I30: Reviewed | K30: Sofia | L30: xml | M30: automated script | N30: unstructured text | O30: Gutenberg - INSTEAD THIS WAS USED https://www.gersum.org/texts/show?occurrences=Gaw - this is also in list 'Downloaded' | Q30: inserted to PROIEL for evaluations, https://dialing.enl.uoa.gr/proiel/sources/80 | S30: Effort required (*/a few hours, **/a few days, /*** a few weeks, ****/a few months) | T30: **
A31: athdgc.002.011.enm.000.000.v1 | B31: added | C31: Sir Orfeo | D31: Source text | E31: late 13th-14th century | F31: Middle English | G31: Anonymous: Sir Orfeo-Middle English Breton Lays-TEST1 | H31: Uploaded to Proiel | I31: Reviewed | J31: Eleni,Sofa | K31: Eleni,Sofa | L31: docx | M31: automated script | N31: Sent by email to Thodoris | O31: METS | Q31: Used https://metseditions.org/texts/A4GxkPrUzD59hz0LcavGPc7152ZE6Wz
A32: athdgc.002.008.ang.000.000.v1 | B32: added | C32: The Battle of Maldon | D32: Source text | E32: 10th century CE | F32: Old English | G32: Anonymous: The Battle of Maldon-TEST3 | H32: Uploaded to Proiel | I32: Reviewed | J32: Eleni | K32: Eleni | L32: docx | M32: automated script | N32: Sent by email to Thodoris | O32: https://www.sacred-texts.com/neu/ascp/a09.htm, ./data/The-Battle-of-Maldon-2025-08.html | P32: ./data/The-Battle-of-Maldon-html-ang-test3-stage1.xml | R32: readStructuredText-The-Battle-of-Maldon-ang-test2.ipynb
A33: athdgc.002.003.ang.000.000.v1 | B33: added | C33: The Dream of the Rood | D33: Source text | E33: 10th century CE | F33: Old English | G33: Anonymous: Dream of the Rood-TEST1 | H33: Uploaded to Proiel | I33: To be reviewed | J33: Eleni | K33: Sofia | L33: txt | M33: automated script | N33: On OSF | O33: https://www.sacred-texts.com/neu/ascp/a02_05.htm
A34: athdgc.002.004.ang.000.000.v1 | B34: added | C34: The Seafarer | D34: Source text | E34: 10th century CE | F34: Old English | G34: Anonymous: The Seafarer-TEST1 | H34: Uploaded to Proiel | I34: Reviewed | J34: Eleni | K34: Eleni | L34: docx | M34: automated script | N34: On OSF | O34: https://www.sacred-texts.com/neu/ascp/a03_09.htm
A35: athdgc.002.002.ang.000.000.v1 | B35: added | C35: The Wanderer | D35: Source text | E35: 10th century CE | F35: Old English | G35: Anonymous: The Wanderer-TEST1 | H35: Uploaded to Proiel | I35: Reviewed | J35: Eleni | K35: Eleni | L35: docx | M35: automated script | N35: Sent by email to Thodoris | O35: https://www.sacred-texts.com/neu/ascp/a03_06.htm
A36: athdgc.001.001n.grc.ell.008.v1 | B36: added | C36: Alexandros Palles: Η Νέα Διαθήκη : κατά το Βατικανό Χειρόγραφο-Πληρες Κείμενο-1 | D36: Translation | E36: 20th century CE | F36: Modern Greek | G36: Alexandros Palles: Η Νέα Διαθήκη : κατά το Βατικανό Χειρόγραφο-Πληρες Κείμενο-1 | H36: Reviewed in Proiel | I36: To be annotated | M36: automated script
A37: athdgc.001.001n.grc.ell.001.v1 | B37: added | C37: Hellenic Bible Society: Η Καινή Διαθήκη σε μετάφραση στη Δημοτική (TGV) - ΕΥΑΓΓΕΛΙΟ ΚΑΤΑ ΜΑΤΘΑΙΟΝ/ΕΥΑΓΓΕΛΙΟ ΚΑΤΑ ΜΑΡΚΟΝ | D37: Translation | E37: 20th - 21st century CE | F37: Modern Greek | G37: Hellenic Bible Society: Η Καινή Διαθήκη σε μετάφραση στη Δημοτική (TGV) - ΕΥΑΓΓΕΛΙΟ ΚΑΤΑ ΜΑΤΘΑΙΟΝ/ΕΥΑΓΓΕΛΙΟ ΚΑΤΑ ΜΑΡΚΟΝ | H37: Reviewed in Proiel | I37: To be annotated | M37: automated script
A38: athdgc.002.013.ell.000.000.v1 | B38: added | C38: Ανώνυμος: Το Χρονικό του Μορέως | D38: Source text | E38: 14th century CE | F38: Modern Greek | G38: Ανώνυμος: Το Χρονικό του Μορέως | H38: Reviewed in Proiel | I38: To be annotated | M38: automated script
A39: athdgc.001.001n.grc.ell.009.v1 | B39: added | C39: Maximos of Gallipoli: Η ΚΑΙΝΗ ΔΙΑΘΗΚΗ ΤΟΥ ΚΥΡΙΟΥ ΗΜΩΝ ΙΗΣΟΥ ΧΡΙΣΤΟΥ-ΚΑΤΑ ΜΑΤΘΑΙΟ-ΚΑΤΑ ΜΑΡΚΟΝ | D39: Translation | E39: 17th century CE | F39: Modern Greek | G39: Maximos of Gallipoli: Η ΚΑΙΝΗ ΔΙΑΘΗΚΗ ΤΟΥ ΚΥΡΙΟΥ ΗΜΩΝ ΙΗΣΟΥ ΧΡΙΣΤΟΥ-ΚΑΤΑ ΜΑΤΘΑΙΟ-ΚΑΤΑ ΜΑΡΚΟΝ | H39: Reviewed in Proiel | I39: To be annotated | M39: automated script
A40: athdgc.001.001.001.ell.010.v1 | B40: added | C40: Νεόφυτος Βάμβας: Η Αγία Γραφή (Παλαιά και Καινή Διαθήκη) στη μετάφραση Νεόφυτου Βάμβα (MNB) - ΚΑΤΑ ΤΟ ΜΑΤΘΑΙΟ-ΚΑΤΑ ΤΟ ΜΑΡΚΟ | D40: Translation | E40: 19th century CE | F40: Modern Greek | G40: Νεόφυτος Βάμβας: Η Αγία Γραφή (Παλαιά και Καινή Διαθήκη) στη μετάφραση Νεόφυτου Βάμβα (MNB) - ΚΑΤΑ ΤΟ ΜΑΤΘΑΙΟ-ΚΑΤΑ ΤΟ ΜΑΡΚΟ | H40: Reviewed in Proiel | I40: To be annotated | M40: automated script
A41: athdgc.002.014.ell.000.000.v1 | B41: added | C41: D. C. Hesseling: Le roman de Digénis Akritas [ανάτυπο] / D. C. Hesseling. - TEST1 | D41: Source text | E41: 19th century CE | F41: Modern Greek | G41: D. C. Hesseling: Le roman de Digénis Akritas [ανάτυπο] / D. C. Hesseling. - TEST1 | H41: Reviewed in Proiel | I41: To be annotated | M41: automated script
A42: athdgc.010.001.lat.ell.018.v1 | B42: added | C42: Μάξιμος Πλανούδης: ΒΟΗΘΙΟΥ ΒΙΒΛΟΣ - ΠΕΡΙ ΠΑΡΑΜΥΘΙΑΣ - ΒΙΒΛΙΟ Α,Β,Γ,Δ - ΔΟΚ-3 | D42: Translation | E42: 13th century CE | F42: Modern Greek | G42: Μάξιμος Πλανούδης: ΒΟΗΘΙΟΥ ΒΙΒΛΟΣ - ΠΕΡΙ ΠΑΡΑΜΥΘΙΑΣ - ΒΙΒΛΙΟ Α,Β,Γ,Δ - ΔΟΚ-3 | H42: Reviewed in Proiel | I42: To be annotated | M42: automated script
A43: athdgc.002.015.ell.000.000.v1 | B43: added | C43: Άσμα του Αρμούρη / Song of Armouris | D43: Source text | E43: 11th-12th century CE | F43: Medieval Greek | G43: Anonymous: ΤΟ ΑΣΜΑ ΤΟΥ ΑΡΜΟΥΡΗ-TEST2 | H43: Reviewed in Proiel | I43: To be annotated | J43: Eleni | K43: Vasilis | L43: docx | M43: automated script | N43: On OSF | O43: http://users.uoa.gr/~nektar/arts/tributes/poetry_of_romania/armoyrhs.htm
...

Sheet On Proeil
G1: REVIEW
A2: Title | C2: Source text/Translation | D2: Status | E2: Language | F2: Annotation | G2: Sentence & token division | H2: Sections | I2: Metadata | J2: Currently reviewed by | K2: Comments
A3: ANCIENT GREEK
A4: The Septuagint (Swete) | B4: added | C4: Translation | D4: Ready | E4: ANCIENT GREEK
A5: Herodotus: Histories | B5: added | C5: Source | D5: Ready | E5: ANCIENT GREEK | F5: Yes
A6: Homer: Odyssey-Treebank-TEST2 | B6: added | C6: Source | D6: Uploaded | E6: ANCIENT GREEK | G6: OK | H6: OK
A7: Homer: Iliad-Treebank-TEST1 | B7: added | C7: Source | D7: Uploaded | E7: ANCIENT GREEK | H7: OK
A8: Ευριπίδης: Μήδεια-TEST13 | B8: added | C8: Source | D8: Uploaded | E8: ANCIENT GREEK | J8: Natasa | K8: Να ελεγχθούν οι σκηνικές οδηγίες
A9: Αισχύλος: Αγαμέμνων-TEST4 | B9: added | C9: Source | D9: Uploaded | E9: ANCIENT GREEK | J9: Natasa | K9: Να ελεγχθούν οι σκηνικές οδηγίες
A10: Αισχύλος: Χοηφόροι-TEST3 | B10: added | C10: Source | D10: Uploaded | E10: ANCIENT GREEK | J10: Natasa | K10: Να ελεγχθούν οι σκηνικές οδηγίες
A11: Αισχύλος: Ευμενίδες-TEST2 | B11: added | C11: Source | D11: Uploaded | E11: ANCIENT GREEK | J11: Natasa | K11: Να ελεγχθούν οι σκηνικές οδηγίες
A12: Ησίοδος: Έργα και Ημέρες-TEST3 | B12: added | C12: Source | D12: Uploaded | E12: ANCIENT GREEK
A13: Ησίοδος: ΘΕΟΓΟΝΙΑ-TEST1 | B13: added | C13: Source | D13: Uploaded | E13: ANCIENT GREEK
A14: Απολλώνιος Ρόδιος: Αργοναυτικά-TEST1 | B14: added | C14: Source | D14: Uploaded | E14: ANCIENT GREEK
A15: Polybius: Ἱστορίαι-TEST1 | B15: added | C15: Source | D15: Uploaded | E15: ANCIENT GREEK
A16: Diodorus Siculus: Βιβλιοθήκη Ἱστορική (Books 1-5, 11-17, 18-20)-TEST2 | B16: added | C16: Source | D16: Uploaded | E16: ANCIENT GREEK
A17: Procopius: Ὑπὲρ τῶν Πολέμων Λόγοι-TEST1 | B17: added | C17: Source | D17: Uploaded | E17: ANCIENT GREEK
A18: Ευριπίδης: Βάκχαι-TEST3 | B18: added | C18: Source | D18: Uploaded | E18: ANCIENT GREEK | J18: Natasa | K18: Να ελεγχθούν οι σκηνικές οδηγίες
A19: Plato: Πολιτεία-TEST1 | B19: added | C19: Source | D19: Uploaded | E19: ANCIENT GREEK
A20: Aristotle: Ἠθικὰ Νικομάχεια-TEST1 | B20: added | C20: Source | D20: Uploaded | E20: ANCIENT GREEK
A21: Flavius Josephus: Ἰουδαϊκὴ ἀρχαιολογία-TEST4-noargs | B21: added | C21: Source | D21: Uploaded | E21: ANCIENT GREEK
A22: Hippocrates: Περὶ ἱερῆς νούσου-TEST1 | B22: added | C22: Source | D22: Uploaded | E22: ANCIENT GREEK
A23: Aristophanes: Thesmophoriazusae-TEST1 | B23: added | C23: Source | D23: Uploaded | E23: ANCIENT GREEK
A24: Aristophanes: Lysistrata-TEST2 | B24: added | C24: Source | D24: Uploaded | E24: ANCIENT GREEK
A25: Aristophanes: Ecclesiazusae-TEST1 | B25: added | C25: Source | D25: Uploaded | E25: ANCIENT GREEK
A26: Aristophanes: Birds-TEST1 | B26: added | C26: Source | D26: Uploaded | E26: ANCIENT GREEK
A27: Aristophanes: Clouds-TEST1 | B27: added | C27: Source | D27: Uploaded | E27: ANCIENT GREEK
A28: Sophocles: Antigone-TEST1 | B28: added | C28: Source | D28: Uploaded | E28: ANCIENT GREEK
A29: Sophocles: Electra-TEST1 | B29: added | C29: Source | D29: Uploaded | E29: ANCIENT GREEK
A31: ENGLISH
A32: Jane Austen: Pride and Prejudice | B32: added | C32: Source | D32: Uploaded | E32: ENGLISH
A33: William Tyndale: The first New Testament printed in English-New Testament-TEST2 | B33: added | C33: Translation | D33: Uploaded | E33: ENGLISH
A34: William Tyndale: The first New Testament printed in English-Old Testament-TEST2 | B34: added | C34: Translation | D34: Uploaded | E34: ENGLISH | G34: OK | K34: Old Testament
A35: William Tyndale: The first New Testament printed in English - Sample from First Chapter for Learning how to Annotate | K35: Προηγούμενη έκδοση
A36: Euripides: Medea-TEST11 | B36: added | C36: Translation | D36: Uploaded | E36: ENGLISH | K36: Δε σημειώνονται όλοι οι στίχοι, αλλά η αρίθμηση υπάρχει ανά πέντε στίχους (ίσως δυσκολέψει την αντιστοίχηση με τα άλλα δύο κείμενα της Μήδειας)
A37: A.J. Wyatt: The Tale of Beowulf Sometime King of the Folk of the Weder Geats-TEST2 | B37: added | C37: Translation | D37: Uploaded | E37: ENGLISH
A38: Boethius, d. 524.: Anicius Manlius Severinus Boetius, Of the consolation of philosophy in five books. | B38: added | C38: Translation | D38: Uploaded | E38: ENGLISH
A39: Simon de Freine, Jean de Meun: Boethius: De Consolatione Philosophiae-TEST1 | B39: added | C39: Translation | D39: Uploaded | E39: ENGLISH
A40: Catholic seminary English College, Douai, France: The Holy Bible in English, Douay-Rheims American Edition of 1899, translated from the Latin Vulgate-TEST2 | B40: added | C40: Translation | D40: Uploaded | E40: ENGLISH
A41: Robert Young: Young's Literal Translation-TEST2 | B41: added | C41: Translation | D41: Uploaded | E41: ENGLISH
...

Sheet Problems
A2: New Revised Standard Version (NRSV) | B2: Translation | C2: 1989 | D2: Division of Christian Education of the National Council of the Churches of Christ in the United States of America | E2: "the copyright is held by the National Council of the Churches of Christ in the United States of America. Specifically, you can use up to 500 verses without permission, as long as it's not a complete book and doesn't exceed 50% of the target publication" | F2: Internet Archive
E3: Παρότι είναι από το Internet Archive δεσμεύεται από copyright
A4: Erotokritos - by Vitsentzos Kornaros | B4: Source text | C4: 17th century CE | D4: Modern Greek | E4: Downloaded | F4: Eleni | G4: PDF | H4: Many editions _On Zenodo (φάκελος Σημαντικά) | I4: Ανέμη (1909) | J4: Ανέμη (1915) | K4: Ανέμη (1859) | L4: Ανέμη (1881) | M4: Ανέμη (1977)
I5: Ποια από όλες τις εκδόσεις;;;;
A7: Slavonic Bible - Cyril and Methodius | B7: Μετάφραση | C7: 9th century CE | D7: Old Church Slavonic (from Greek) | E7: To be downloaded | I7: https://mudroljub.github.io/old-slavic-library/
E8: Επίσης έχει πολλαπλές εκδοχές
A10: Modern Greek Bible | B10: 2003 | C10: Greek Bible Society | D10: Contemporary Greek | E10: Online Text | F10: ΝΑΙ | G10: Από το bible.com, έχει πνευματικά δικαιώματα, αλλά εκδότης είναι η βιβλική εταιρεία, οπότε ίσως θα μπορούσαμε να τους ζητήσουμε την άδεια και για αυτές τις εκδόσεις αν μας ενδιαφέρουν | J10: Όλη η βίβλος: bible.com
B11: Όλες οι εκδόσεις σε νέα ελληνικά:
B12: Copyright © The Holy Bible, Spyros Filos Translation, copyright 1994, latest edition 2013, by Pergamos Publications, 23, Averof Street, 104 33 Athens, Greece – www.pergamos.com.gr – pergamos@otenet.gr. All rights reserved.
B13: Νεοελληνική Μετάφραση Λόγου 1994, 2004, 2021 LOGOS, AMG International [από τις εκδόσεις 'ο Λόγος']
B14: Η Καινή Διαθήκη του Κυρίου και Σωτήρος ημών Ιησού Χριστού κατά νεοελληνικήν απόδοσιν [Hellenic Bible Society_1967_NTV PUBLISHER]
B15: Cata Lucan Evanghelion ke e Praxis ton Apostolon 1859 (Frangochiatika) - Gospel of Luke and the Acts of the Apostles published by the British and Foreign Bible Society (BFBS) in 1859 in Smyrna in the Ottoman Empire, edited by T.J. Wolters with the help of a Greek named N. Vamvas and other
A16: ήδη στο PROEIL | B16: Η Αγία Γραφή (Παλαιά και Καινή Διαθήκη) - Hellenic Bible Society_2003_TGV PUBLISHER
B17: Η Αγία Γραφή με τα Δευτεροκανονικά (Παλαιά και Καινή Διαθήκη) - Hellenic Bible Society_2003_TGVD PUBLISHER, ίδιο με το πάνω, αλλά περιέχει και τα δευτεροκανονικά
B18: Περιέχει επίσης πολλές εκδόσεις του πρωτοτύπου (σε ελληνιστική κοινή): 1.Έκδοση Αντωνιάδη(1904, εγκεκριμένη από το Πατριαρχείο), 2.Byzantine Textform 2018(according to its historically dominant transmissional form), 3.Η Ελληνική Καινή Διαθήκη Σύμφωνα με την Οικογένεια 35 (The Byzantine Majority Text, also known as Family 35, a specific group of NT manuscripts that represent the Byzantine text-type, which dominated New Testament manuscript production during the late Byzantine Empire (1261-1453)), 4.μετάφρση των εβδομήκοντα, 5.New Vellas Source Text (1967, a team of academic staff of the University of Athens led by Basil (Vasilios) Vellas (Βασίλειος Βέλλας) translated the New Testament, with support from the Hellenic Bible Society, based on the Textus Receptus), 6.SBL Greek New Testament (Copyright 2010 by the Society of Biblical Literature and Logos Bible Software), 7.Text-Critical Greek New Testament(a 2022 edition of Robinson and Pierpont's Byzantine Greek text that documents variants found in eleven editions of the Greek New Testament), 8.The Greek New Testament, copyright © 2017 by Tyndale House, Cambridge. Used by permission of Crossway, a publishing ministry of Good News Publishers, 9.Elzevir Textus Receptus 1624, 10.Scrivener’s Textus Receptus 1894(F. H. A. Scrivener (1813-1891) attempted to reproduce as exactly as possible the Greek text which underlies the Authorised Version of 1611)

Sheet Timeline
A1: OLD ENGLISH (449/5th c. – 1150)
A2: - Beowulf: 700-750
A3: - Dream of the Rood: uncertain, believed to have been composed in the late 7th or early 8th century [certainly 8th c. or earlier, in late West Saxon],
A4: - Anglo-Saxon Chronicles: between 890 and 892 AD
A5: -The Wanderer: late 9th or early 10th century
A6: - The Seafarer: uncertain date (before 10th c.)
A7: - Orosius: around 900 AD
A8: - West-Saxon Gospels: c. 990 AD
A9: - The Battle of Maldon: dates from the 990s AD (no earlier than 991 AD)
A10: - Ælfric's Lives of Saints
A11: - Apollonius of Tyre (transl.): 11th century AD
A13: MIDDLE ENGLISH (1150/12th c.-15th c.)
... A72: MODERN FRENCH (16th/17th c.-)

Sheet Overview
B1: UPLOADED | C1: ANNOTATED
A2: ANCIENT GREEK | B2: =COUNTIF('On Proeil'!E:E, A2) -> 26 | C2: =COUNTIFS('On Proeil'!E:E, A2, 'On Proeil'!F:F, "<>") -> 1
A3: MODERN GREEK | B3: =COUNTIF('On Proeil'!E:E, A3) -> 14 | C3: =COUNTIFS('On Proeil'!E:E, A3, 'On Proeil'!F:F, "<>") -> 3
A4: ENGLISH | B4: =COUNTIF('On Proeil'!E:E, A4) -> 27 | C4: =COUNTIFS('On Proeil'!E:E, A4, 'On Proeil'!F:F, "<>") -> 0
A5: MIDDLE ENGLISH | B5: =COUNTIF('On Proeil'!E:E, A5) -> 9 | C5: =COUNTIFS('On Proeil'!E:E, A5, 'On Proeil'!F:F, "<>") -> 0
A6: OLD ENGLISH | B6: =COUNTIF('On Proeil'!E:E, A6) -> 10 | C6: =COUNTIFS('On Proeil'!E:E, A6, 'On Proeil'!F:F, "<>") -> 5
A7: LATIN | B7: =COUNTIF('On Proeil'!E:E, A7) -> 7 | C7: =COUNTIFS('On Proeil'!E:E, A7, 'On Proeil'!F:F, "<>") -> 6
A8: GOTHIC | B8: =COUNTIF('On Proeil'!E:E, A8) -> 1 | C8: =COUNTIFS('On Proeil'!E:E, A8, 'On Proeil'!F:F, "<>") -> 1
A9: OLD HIGH GERMAN | B9: =COUNTIF('On Proeil'!E:E, A9) -> 1 | C9: =COUNTIFS('On Proeil'!E:E, A9, 'On Proeil'!F:F, "<>") -> 0
A10: OLD FRENCH | B10: =COUNTIF('On Proeil'!E:E, A10) -> 3 | C10: =COUNTIFS('On Proeil'!E:E, A10, 'On Proeil'!F:F, "<>") -> 1
A11: MODERN FRENCH | B11: =COUNTIF('On Proeil'!E:E, A11) -> 2 | C11: =COUNTIFS('On Proeil'!E:E, A11, 'On Proeil'!F:F, "<>") -> 0
B13: =sum(B2:B11) -> 100 | C13: =sum(C2:C11) -> 17

Sheet Languages
A2: Ancient Greek | B2: Latin
A3: Medieval Greek | B3: Old Gothic
A4: Koine Greek | B4: Old French
A5: Middle English | B5: Old English
A6: Old English | B6: Modern Greek
A7: Modern English | B7: Ancient Greek
A8: Early Modern English | B8: Modern English
A9: Middle French | B9: Modern English [from Medieval Greek]
A10: Modern Greek | B10: Early Modern English
A11: Medieval English | B11: Middle English
A12: Atticized Medieval Greek | B12: Old English
A13: Medieval Latin | B13: Modern Greek
... A18: Late Middle English | B18: Old High German
A19: Gothic
A20: `

Sheet temp
A1: Title/Author | B1: Source text/Translation | C1: Period | D1: Language | E1: Original Format | F1: Original Download method | G1: Original Source
A2: Jerome's Vulgate | B2: Translation | C2: 4th century CE | D2: Latin | E2: proiel treebank | F2: proiel treebank | G2: ./data/syntacticus-treebank-data/proiel/latin-nt-1.xml
A3: Caesar: Commentarii belli Gallici | B3: Source text | C3: 1st century BCE | D3: Latin | E3: proiel treebank | F3: proiel treebank | G3: ./data/syntacticus-treebank-data/proiel/caes-gal-1.xml
A4: Cicero: Epistulae ad Atticum | B4: Source text | C4: 1st century BCE | D4: Latin | E4: proiel treebank | F4: proiel treebank | G4: ./data/syntacticus-treebank-data/proiel/cic-att-1.xml
A5: Cicero: De officiis | B5: Source text | C5: 1st century BCE | D5: Latin | E5: proiel treebank | F5: proiel treebank | G5: ./data/syntacticus-treebank-data/proiel/cic-off-1.xml
A6: Palladius: Opus agriculturae | B6: Source text | C6: 5th century CE | D6: Latin | E6: proiel treebank | F6: proiel treebank | G6: ./data/syntacticus-treebank-data/proiel/pal-agr-1.xml
A7: Peregrinatio Aetheriae | B7: Source text | C7: 4th century CE | D7: Latin | E7: proiel treebank | F7: proiel treebank | G7: ./data/syntacticus-treebank-data/proiel/per-aeth-1.xml
A8: La Vie Saint Eustace | B8: Source text | C8: 12th century CE | D8: Old French | E8: proiel treebank | F8: proiel treebank | G8: ./data/iswoc-treebank/eustace-1.xml
A9: Orosius | B9: Source text | C9: 5th century CE | D9: Old English | E9: proiel treebank | F9: proiel treebank | G9: ./data/iswoc-treebank/or-1.xml
A10: West-Saxon Gospels | B10: Translation | C10: 10th century CE | D10: Old English | E10: proiel treebank | F10: proiel treebank | G10: ./data/iswoc-treebank/wscp-1.xml
A11: Anglo-Saxon Chronicles | B11: Source text | C11: 9th - 12th century CE | D11: Old English | E11: proiel treebank | F11: proiel treebank | G11: ./data/iswoc-treebank/chrona-1.xml
A12: Ælfric's Lives of Saints | B12: Source text | C12: 10th century CE | D12: Old English | E12: proiel treebank | F12: proiel treebank | G12: ./data/iswoc-treebank/æls.xml
... A16: Histories - by Herodotus | B16: Source text | C16: 5th century BCE | D16: Ancient Greek | E16: proiel treebank | F16: proiel treebank | G16: ./data/syntacticus-treebank-data/proiel/hdt.xml

Sheet To be downloaded(depr)
A1: Αντιγόνη Ζωγραφάκη | B1: Source text/Translation | C1: Translator | D1: Period | E1: Language | F1: Status | G1: Contributors so far | H1: Format | I1: Comments | J1: Download method | K1: ASSIGNEE | L1: STATUS | M1: Effort required (*/a few hours, **/a few days, /*** a few weeks, ****/a few months) | N1: Source
A3: Iliad | B3: Source text | D3: 8th century BCE | E3: Ancient Greek | F3: To be downloaded | I3: structured info, there is also a UD treebank in https://github.com/UniversalDependencies/UD_Ancient_Greek-Perseus | J3: automated script | K3: THEO/experimental import on proiel | L3: inserted to PROIEL for evaluation, USED treebank data, https://dialing.enl.uoa.gr/proiel/sources/68 | M3: ** | N3: Perseus
A4: Homer's Iliad | B4: Translation | C4: Eustathius of Thessalonica | D4: 12th century CE | E4: Medieval Greek | F4: To be downloaded | I4: OCRed text | J4: manual preprocessing | M4: ** | N4: Internet Archive
A5: Homer's Iliad | B5: Translation | D5: 11th century CE | E5: Medieval Greek | F5: To be downloaded | H5: Scanned manuscript | I5: This requires OCR - we maybe able to use some help from CHS that specializes in IIIF formats | J5: automated script | K5: THEO/experimental import on proiel | M5: *** | N5: Vatican Library
A6: Odyssey | B6: Source text | D6: 8th century BCE | E6: Ancient Greek | F6: To be downloaded | I6: structured info, there is also a GAGDT 2.0 treebank in https://github.com/PerseusDL/treebank_data/tree/master/v2.1/Greek | J6: automated script | K6: THEO/experimental import on proiel | L6: inserted to PROIEL for evaluation, USED treebank data, https://dialing.enl.uoa.gr/proiel/sources/68 | M6: ** | N6: Perseus
A7: Works and Days - by Hesiod | B7: Source text | D7: 7th century BCE | E7: Ancient Greek | F7: To be downloaded | I7: structured info, there is also a UD bank at https://github.com/UniversalDependencies/UD_Ancient_Greek-Perseus | J7: automated script | K7: THEO | L7: inserted to PROIEL for evaluation, USED CanonicalLit data https://dialing.enl.uoa.gr/proiel/sources/77 | M7: ** | N7: Perseus
A8: Histories - by Herodotus | B8: Source text | D8: 5th century BCE | E8: Ancient Greek | F8: To be downloaded | I8: structured info, there is also a UD bank at https://github.com/UniversalDependencies/UD_Ancient_Greek-Perseus | J8: automated script | K8: THEO | L8: the first five books are available from proiel treebanks at https://dialing.enl.uoa.gr/proiel/sources/39 | M8: ** | N8: Perseus
A9: Republic - by Plato | B9: Source text | D9: 4th century BCE | E9: Ancient Greek | F9: To be downloaded | I9: structured info, no treebank available | J9: automated script | K9: THEO | L9: the first five books are available from proiel treebanks athttps://dialing.enl.uoa.gr/proiel/sources/85 | M9: ** | N9: Perseus
A10: Nicomachean Ethics - by Aristotle | B10: Source text | D10: 4th century BCE | E10: Ancient Greek | F10: To be downloaded | I10: structured info, no treebank available | J10: automated script | K10: THEO | L10: the first five books are available from proiel treebanks a https://dialing.enl.uoa.gr/proiel/sources/86 | M10: ** | N10: Perseus
A11: The Argonautica - by Apollonius of Rhodes | B11: Source text | D11: 3rd century BCE | E11: Ancient Greek | F11: To be downloaded | I11: structured info, no treebank available | J11: automated script | K11: THEO | L11: inserted to PROIEL for evaluation, USED CanonicalLit data, https://dialing.enl.uoa.gr/proiel/sources/79 | M11: ** | N11: Perseus
A12: Histories - by Polybius | B12: Source text | D12: 2nd century BCE | E12: Koine Greek | F12: To be downloaded | I12: structured info, there is also a GAGDT 2.0 treebank in https://github.com/PerseusDL/treebank_data/tree/master/v2.1/Greek | J12: automated script | K12: THEO | L12: inserted to PROIEL for evaluation, USED CanonicalLit data, https://dialing.enl.uoa.gr/proiel/sources/81 | M12: ** | N12: Perseus
A13: Bibliotheca Historica - by Diodorus Siculus | B13: Source text | D13: 1st century BCE | E13: Koine Greek | F13: To be downloaded | I13: structured info, there is also a UD bank at https://github.com/UniversalDependencies/UD_Ancient_Greek-Perseus | J13: automated script | K13: THEO | L13: inserted to PROIEL for evaluation, USED CanonicalLit data, https://dialing.enl.uoa.gr/proiel/sources/82 | M13: ** | N13: Perseus
A14: The Antiquities of the Jews | B14: Source text | D14: 1st century BCE | E14: Koine Greek | F14: To be downloaded | I14: structured info, no treebank available | J14: automated script | K14: THEO | L14: inserted to PROIEL for evaluation, USED CanonicalLit data, https://dialing.enl.uoa.gr/proiel/sources/88 | M14: ** | N14: Perseus
A15: Wars / de Bellis - by Procopius | B15: Source text | D15: 6th century CE | E15: Medieval Greek | F15: To be downloaded | I15: structured info, no treebank available | J15: automated script | K15: THEO | L15: inserted to PROIEL for evaluation, USED CanonicalLit data, https://dialing.enl.uoa.gr/proiel/sources/83 | M15: ** | N15: Perseus
A16: Theogony - by Hesiod | B16: Source text | D16: 7th century BCE | E16: Ancient Greek | F16: To be downloaded | I16: structured info, there is also a UD bank at https://github.com/UniversalDependencies/UD_Ancient_Greek-Perseus | J16: automated script | K16: THEO | L16: inserted to PROIEL for evaluation, USED CanonicalLit data, https://dialing.enl.uoa.gr/proiel/sources/78 | M16: ** | N16: Perseus
A17: Oresteia - by Aeschylus | B17: Source text | D17: 5th century BCE | E17: Ancient Greek | F17: To be downloaded | I17: From Perseus (3 plays), structured info, there is also a UD bank at https://github.com/UniversalDependencies/UD_Ancient_Greek-Perseus | J17: automated script | K17: THEO | L17: inserted to PROIEL for evaluation, USED CanonicalLit data, Αγαμέμνων (ενημερωμένη έκδοση), Χοηφόροι, Ευμένιδες. https://dialing.enl.uoa.gr/proiel/sources/74, https://dialing.enl.uoa.gr/proiel/sources/75, https://dialing.enl.uoa.gr/proiel/sources/76 | M17: ** | N17: Agamemnon | O17: Libation Bearers | P17: Eumenides
A18: On the Sacred Disease - by Hippocrates | B18: Source text | D18: 5th century BCE | E18: Ancient Greek | F18: To be downloaded | I18: structured info, no treebank available | J18: automated script | K18: THEO | L18: inserted to PROIEL for evaluation, USED CanonicalLit data, https://dialing.enl.uoa.gr/proiel/sources/89 | M18: ** | N18: Perseus
A19: Bacchae | B19: Source text | D19: 5th century BCE | E19: Ancient Greek | F19: To be downloaded | I19: structured info, no treebank available | J19: automated script | K19: THEO | L19: inserted to PROIEL for evaluation, USED CanonicalLit data, https://dialing.enl.uoa.gr/proiel/sources/84 | M19: ** | N19: Perseus
A20: Sir Gawain and the Green Knight | B20: Source text | D20: 14th century CE | E20: Middle English | F20: To be downloaded | I20: unstructured text | J20: automated script | K20: SOFIA/THEO | L20: inserted to PROIEL for evaluations, https://dialing.enl.uoa.gr/proiel/sources/80 | M20: ** | N20: Gutenberg - INSTEAD THIS WAS USED https://www.gersum.org/texts/show?occurrences=Gaw - this is also in list 'Downloaded'
A21: Slavonic Bible | B21: Translation | C21: Cyril and Methodius | D21: 9th century CE | E21: Old Church Slavonic (from Greek) | F21: To be downloaded | I21: PDF with text - CHECK IF THERE IS A PROIEL TREEBANK | J21: manual preprocessing | K21: ELENI | M21: ** | N21: https://mudroljub.github.io/old-slavic-library/
A22: Gospel Lectionary | B22: Translation | D22: 10th century CE | E22: Medieval Greek | F22: To be downloaded | H22: Scanned manuscript | I22: This requires OCR - we maybe able to use some help from CHS that specializes in IIIF formats | J22: manual preprocessing/CHS | K22: THEO | M22: *** | N22: Manuscript 1 | O22: Manuscript 2
A23: Old English Hexateuch | B23: Translation | D23: 10th century CE | E23: Old English | F23: To be downloaded | H23: Scanned manuscript | I23: This requires OCR - we maybe able to use some help from CHS that specializes in IIIF formats | J23: manual preprocessing /CHS | K23: THEO | M23: *** | N23: Cambridge
A24: Old English Psalter | B24: Translation | D24: 10th century CE | E24: Old English | F24: To be downloaded | H24: Online text | I24: Hard to find: need to scrool downpassing the Overview, then click on one of the excerpts, then click on the text we want to see, then scroll dwon again to find the few lines of the excerpt/This requires OCR - we maybe able to use some help from CHS that specializes in IIIF formats | J24: manual preprocessing /CHS | K24: THEO | M24: *** | N24: https://oepoetryfacsimile.org/?document=11191
A25: Boethius' Consolation of Philosophy | B25: Translation | C25: Peter Glassgold | D25: c.2019 CE - original 524 CE | E25: Modern English | F25: To be downloaded | H25: Images | I25: 3 excerpts from the sample images on an eshop - not clear what the format is - we need a sample to understand if this is images or it includes text | J25: manual preprocessing | K25: Ελένη | M25: **** | N25: https://worldpoetrybooks.com/books/poems-from-on-the-consolation-of-philosophy
A26: Boethius' Consolation of Philosophy | B26: Translation | C26: Richard Preston | D26: c. 1695 CE - original 524 CE | E26: Early Modern English | F26: To be downloaded | I26: structured info | J26: automated script | K26: THEO | M26: ** | N26: Michigan Library
A27: Boethius' Consolation of Philosophy | B27: Translation | C27: Scott Goins & Barbara H. Wyman | D27: 2008 CE | E27: Modern English | F27: To be downloaded | I27: 15-page sample on Amazon | J27: manual preprocessing | K27: Ελένη | N27: sample on Amazon
A28: Cato's Distichs | B28: Translation | C28: Maximus Planudes | D28: 13th century CE | E28: Medieval Greek | F28: To be downloaded | I28: Harvard copy | J28: manual preprocessing | K28: THEO | M28: ** | N28: HathiTrust [starts on p.275, #401-522]
A29: Hesiod's Works and Days | B29: Translation | C29: John Tzetzes | D29: 12th century CE - original: 7th c. | E29: Medieval Greek | F29: To be downloaded | H29: Scanned manuscript | I29: This requires OCR - we maybe able to use some help from CHS that specializes in IIIF formats | J29: manual preprocessing /CHS | K29: THEO | M29: *** | N29: Bodleian Library
A30: Greek Psalter | B30: Translation | D30: 11th century CE | E30: Medieval Greek | F30: To be downloaded | H30: Scanned manuscript | I30: This requires OCR - we maybe able to use some help from CHS that specializes in IIIF formats | J30: manual preprocessing /CHS | K30: THEO | M30: *** | N30: Bodleian Library
A31: Boethius' Consolation of Philosophy | B31: Translation | C31: Jean de Meun, Notker | D31: 1609 CE | E31: Middle French | F31: To be downloaded | I31: many parallel translations, de Meun's is the middle column | J31: manual preprocessing | M31: *** | N31: Bibliotheca Polyglotta
A38: Σε δεύτερη φάση
A39: Longus' Daphnis and Chloe | B39: Translation | C39: George Thornley | D39: 1657 CE | E39: Koine Greek | F39: To be downloaded | N39: Wikisource | O39: Internet Archive
A40: Sophocles' Antigone | B40: Translation | C40: George Adams | D40: 1729 CE | E40: Ancient Greek | F40: To be downloaded | N40: Internet Archive
A41: Herodotus' Histories | B41: Translation | C41: Isaac Littlebury | D41: 1709 CE | E41: Ancient Greek | F41: To be downloaded | N41: Τόμος 1 | O41: Τόμος 2
A42: Aesop's Fables | B42: Translation | C42: William Caxton | D42: 1480s CE | E42: Latin | F42: To be downloaded | N42: http://mythfolklore.net/aesopica/caxton/index.htm
A43: Plutarch's Lives | B43: Translation | C43: Thomas North | D43: 1579 CE | F43: To be downloaded | N43: Internet Archive
A44: Thucydides' History | B44: Translation | C44: Thomas Nicolls | D44: 1550 CE | E44: Ancient Greek | F44: To be downloaded | N44: https://quod.lib.umich.edu/e/eebo/A13758.0001.001
A45: The Homeric Hymns | B45: Translation | C45: Andrew Lang | D45: 1899 CE | E45: Ancient Greek | F45: To be downloaded | N45: Gutenberg link
A46: Plutarch's Moralia | B46: Translation | C46: Philemon Holland | D46: 1603 CE | E46: Ancient Greek | F46: To be downloaded | N46: Wikisource link
A47: Plato's Symposium | B47: Translation | C47: Percy Bysshe Shelley | D47: 1818 CE | E47: Ancient Greek | F47: To be downloaded | N47: Internet Archive
...

Sheet Sheet11

Sheet Downloaded(depr)
A1: στο PROEIL | B1: προς επεξεργασία
A2: Title | B2: Source text/Translation | C2: Period | D2: Language | E2: Status | F2: Next step | H2: Contributors so far | I2: Currently handled by | J2: Format | K2: Comments | L2: Source
N3: Notes
A4: Tyndale's Bible | B4: Translation | C4: 1526 | D4: Early Modern English | E4: Uploaded [Old Testament] | H4: Thodoris
A5: Μήδεια | B5: Source text | C5: 5th century CE - edition 1871 | D5: Ancient Greek | E5: Uploaded | F5: Uploaded, To be reviewed from scholars. https://dialing.enl.uoa.gr/proiel/sources/72 | H5: Natasa, Eleni | J5: txt | L5: Perseus
A6: Μήδεια-ελληνικη μεταφραση Στεφανοπουλου | B6: Translation | C6: 1867 | D6: Modern Greek | E6: Uploaded | F6: Uploaded, To be reviewed from scholars https://dialing.enl.uoa.gr/proiel/sources/73 | H6: Natasa, Eleni | J6: docx | K6: On OSF | L6: Πύλη για την ελληνική γλώσσα
A7: The Battle of Maldon | B7: Source text | C7: 10th century CE | D7: Old English | E7: Uploaded | F7: Uploaded, To be reviewed from scholars | H7: Eleni | I7: Thodoris | J7: docx | K7: Sent by email to Thodoris | L7: https://www.sacred-texts.com/neu/ascp/a09.htm
A8: Pride and Prejudice | B8: Source text | C8: 19th century CE | D8: Modern English | E8: Uploaded | F8: Uploaded, To be reviewed from scholars | H8: Eleni, Vangelis | I8: Vangelis/Thodoris | J8: docx | K8: Sent by email to Thodoris | L8: Gutenberg
A9: Lay le Freine | B9: Source text | C9: late 13th-14th century | D9: Old English | E9: Uploaded | F9: Uploaded, To be reviewed from scholars | H9: Eleni | I9: Thodoris | J9: docx | K9: Sent by email to Thodoris | L9: METS
A10: Sir Orfeo | B10: Source text | C10: late 13th-14th century | D10: Old English | E10: Uploaded | F10: Uploaded, To be reviewed from scholars | H10: Eleni | I10: Thodoris | J10: docx | K10: Sent by email to Thodoris | L10: METS | N10: Used https://metseditions.org/texts/A4GxkPrUzD59hz0LcavGPc7152ZE6Wz
A11: The Vision of Piers Plowman | B11: Source text | C11: 14th century CE | D11: Middle English | E11: Uploaded | F11: Uploaded, To be reviewed from scholars | H11: Eleni | I11: Thodoris | J11: docx | K11: Sent by email to Thodoris | L11: Michigan Library
A12: The Wanderer | B12: Source text | C12: 10th century CE | D12: Old English | E12: Uploaded | F12: Uploaded, To be reviewed from scholars | H12: Eleni | I12: Thodoris | J12: docx | K12: Sent by email to Thodoris | L12: https://www.sacred-texts.com/neu/ascp/a03_06.htm
A13: Ormulum | B13: Source text | C13: 12th century CE | D13: Old English | E13: Uploaded | F13: Uploaded, To be reviewed from scholars | H13: Sophia, Eleni | I13: Sophia | J13: docx | K13: On OSF | L13: Michigan library | N13: Used https://quod.lib.umich.edu/c/cme/AFW5744.0001.001/1:7?rgn=div1;view=fulltext - JUST INTRODUCTION chapters were added - SECUNDUM JOHANNEM XXXII. was not added since it is not completely transcribed
A14: Wycliffe Bible | B14: Translation | C14: 1382 | D14: Middle English | E14: Uploaded | F14: Uploaded, To be reviewed from scholars | H14: Sophia, Eleni | I14: Thodoris | J14: docx | K14: On OSF | L14: Wikisource | M14: Used wikisource
A15: Somnium Scipionis Κικέρωνα - μτφρ Πλανούδη | B15: Translation | C15: 13th century | D15: Medieval English | E15: PDF Scan | F15: To be preprocessed | H15: Eleni | J15: PDF (scan) | K15: On OSF | L15: Από έντυπο
A16: Chronographia - Ψελλός | B16: Source text | C16: 11th century CE | D16: Medieval Greek | E16: Uploaded | F16: Uploaded | H16: Eleni | I16: Thodoris | J16: docx | K16: On OSF | L16: https://byzantium.gr/keimena/psellos.php
A17: De Ceremoniis / [Book of Ceremonies] | B17: Source text | C17: 10th century CE [edition: 1829] | D17: Medieval Greek | E17: PDF | F17: To be preprocessed | H17: Eleni | J17: PDF | K17: On OSF | L17: Internet Archive
A18: Alexiad | B18: Source text | C18: 12th century CE | D18: Atticized Medieval Greek | E18: PDF | F18: To be preprocessed | H18: Eleni | I18: Eleni | J18: PDF | K18: On OSF | L18: http://khazarzar.skeptik.net/pgm/PG_Migne/Anna%20Komnena_PG%20131/Alexias.pdf
A19: Greek Anthology - Planudes (ed.) | B19: Source text | C19: 14th century CE | D19: Medieval Greek | E19: Downloaded | F19: To be preprocessed | H19: Eleni | J19: PDF | K19: On OSF | L19: Internet Archive
A20: Byzantine Chronicles - Ζωναράς | B20: Source text | C20: 12th century CE | D20: Medieval Greek | E20: Uploaded | F20: Uploaded | H20: Eleni | J20: PDF | K20: On OSF [1,2,3,4,5,6] | L20: Βικιθήκη
A21: Ptochoprodromos | B21: Source text | C21: 12th century CE | D21: Medieval Greek | E21: Downloaded | F21: To be preprocessed | H21: Eleni | J21: PDF | K21: On OSF | L21: Ανέμη
A22: De Hominis Opificio | B22: Source text | C22: 4th century CE | D22: Medieval Greek | E22: Downloaded | F22: To be preprocessed | H22: Eleni | J22: PDF | K22: On OSF | L22: http://khazarzar.skeptik.net/pgm/PG_Migne/Gregory%20of%20Nyssa_PG%2044-46/De%20opificio%20hominis.pdf
A23: Bibliotheca - by Photius | B23: Source text | C23: 9th century CE | D23: Medieval Greek | E23: PDF | F23: To be preprocessed | H23: Eleni | J23: PDF | K23: On OSF | L23: https://greekdownloads3.wordpress.com/wp-content/uploads/2014/09/bibliotheca.pdf
A24: Coverdale Bible | B24: Translation | C24: 1535 | D24: Early Modern English | E24: PDF | F24: To be preprocessed | H24: Eleni | I24: Sofia | J24: PDF | K24: On OSF | L24: https://evanbible.com/downloads/coverdale.pdf
A25: Geneva Bible | B25: Translation | C25: 1500[1599] | D25: Early Modern English | E25: Downloaded | F25: To be preprocessed | H25: Eleni | I25: Sofia | J25: PDF | K25: On OSF | L25: https://ebible.org/enggnv/
A26: King James Bible | B26: Translation | C26: 1611 | D26: Early Modern English | E26: Downloaded | F26: To be preprocessed | H26: Eleni | I26: Sofia | J26: PDF | K26: On OSF | L26: https://ebible.org/pdf/eng-kjv/eng-kjv_all.pdf
A27: Revised Version | B27: Translation | C27: 1885 | D27: Modern English | E27: Downloaded | F27: To be preprocessed | H27: Eleni | J27: PDF | K27: On OSF | L27: https://ebible.org/pdf/eng-rv/eng-rv_all.pdf
A28: Douay-Rheims Bible | B28: Translation | C28: 1582-1610 | D28: Early Modern English | E28: Downloaded | F28: To be preprocessed | H28: Eleni | I28: Eleni | J28: PDF | K28: On OSF | L28: https://ebible.org/pdf/engDRA/engDRA_all.pdf
A29: Young's Literal Translation | B29: Translation | C29: 1862 | D29: Modern English | E29: Downloaded | F29: To be preprocessed | H29: Eleni | I29: Eleni | J29: PDF | K29: On OSF | L29: https://ebible.org/engylt/
A30: World English Bible | B30: Translation | C30: 2000 | D30: Modern English | E30: Downloaded | F30: To be preprocessed | H30: Eleni | I30: Eleni | J30: PDF | K30: On OSF | L30: https://ebible.org/pdf/engwebp/engwebp_all.pdf
A31: Against Heresies - by Irenaeus | B31: Source text | C31: 2nd century CE | D31: Koine Greek | E31: Downloaded | F31: To be preprocessed | H31: Eleni | J31: PDF | K31: On OSF [1-2, 3, 4, 5] | L31: https://greekdownloads.wordpress.com/2014/09/29/%CE%AC%CE%B3%CE%B9%CE%BF%CF%82-%CE%B5%CE%B9%CF%81%CE%B7%CE%BD%CE%B1%CE%AF%CE%BF%CF%82-%CE%BB%CE%BF%CF%85%CE%B3%CE%B4%CE%BF%CF%8D%CE%BD%CE%BF%CF%85-irenaeus-lugdunensis-pg-07/
A32: Chronographia - by John Malalas | B32: Source text | C32: 6th century CE | D32: Medieval Greek | E32: Downloaded | F32: To be preprocessed | H32: Eleni | J32: PDF | K32: On OSF | L32: Internet Archive
A33: Kontakia - by Romanos the Melodist | B33: Source text | C33: 6th century CE | D33: Medieval Greek
A34: Kontakia - by Romanos the Melodist | B34: Translation [by Marjorie Carpenter] | C34: 1970 [from 6th century CE] | D34: Modern English [from Medieval Greek] | E34: Downloaded | F34: To be preprocessed | H34: Eleni | J34: PDF | K34: Excerpts_On OSF | L34: Internet Archive
A35: Erotokritos - by Vitsentzos Kornaros | B35: Source text | C35: 17th century CE | D35: Modern Greek | E35: Downloaded | F35: To be preprocessed | H35: Eleni | J35: PDF | K35: Many editions _On OSF | L35: Ανέμη (1909) | M35: Ανέμη (1915) | N35: Ανέμη (1977)
A36: Beowulf | B36: Source text | C36: 8th-11th century CE | D36: Old English | E36: Downloaded | F36: To be preprocessed | H36: Eleni | I36: Sofia | J36: txt | K36: On OSF | L36: Gutenberg
A37: Beowulf | B37: Source text | C37: 8th-11th century CE | D37: Old English | E37: Uploaded | F37: Uploaded, To be reviewed from scholars | I37: Sofia | J37: online | L37: https://en.wikisource.org/wiki/Beowulf_(Wyatt)
A38: The Tale of Beowulf | B38: Translation | C38: 19th century | D38: Modern English [from Medieval Greek] | E38: Uploaded | F38: Uploaded, To be reviewed from scholars | I38: Sofia | J38: online | L38: https://en.wikisource.org/wiki/The_Tale_of_Beowulf
A39: The Dream of the Rood | B39: Source text | C39: 10th century CE | D39: Old English | E39: Uploaded | F39: Uploaded, To be reviewed from scholars | H39: Eleni | J39: txt | K39: On OSF | L39: https://www.sacred-texts.com/neu/ascp/a02_05.htm
A40: The Owl and the Nightingale | B40: Source text | C40: 13th century CE | D40: Old English | E40: Uploaded | F40: Uploaded, To be reviewed from scholars | H40: Eleni | J40: txt | K40: On OSF | L40: Michigan Library | N40: Used curl download from https://quod.lib.umich.edu/c/cme/OwlC/1:1?rgn=div1;view=fulltext. Removed folio info, removed brackets from suggested letters
...
